Workbook

Sheet Leia-me
B2: PROGRAMA DE INSPEÇÕES DE CAMPO – CANTEIRO DE OBRAS
B3: Checklists por NR e por área | Cronograma semanal | Base para KPIs
B5: Como usar
B7: 1. Aba CHECKLISTS | C7: Lista mestra com todos os itens de verificação, organizados por código (ex.: ST-03 = NR-10). Cada item recebe UMA resposta: Conforme / Não Conforme / Não Aplicável (validação de dados já configurada).
B9: 2. Campos de resposta | C9: Resposta, Observação, Evidência Fotográfica (Sim/Não), Responsável pela correção, Prazo e Status (Aberto / Em Andamento / Fechado).
B11: 3. Aba CRONOGRAMA | C11: Distribuição semanal das inspeções por dia, com frequência, duração estimada e responsável sugerido. Inspeções 'por evento' (NR-33, trabalho a quente, escavações) são disparadas pela emissão da PT ou abertura da frente.
B13: 4. Aba KPIs | C13: Catálogo de indicadores com fórmula, fonte de dados, frequência de apuração e meta sugerida. Todos podem ser calculados a partir das respostas dos formulários.
B15: Regra de ouro | C15: Todo 'Não Conforme' deve gerar: observação + evidência + responsável + prazo. NC sem plano de ação não fecha indicador.
B17: Estrutura de códigos | C17: ST = Segurança do Trabalho | MA = Meio Ambiente | QA = Qualidade | EQ = Equipamentos | DC = Documentação | VE = Veículos | SO = Saúde Ocupacional | EM = Emergência | CT = Contratadas | PR = Produção
B19: 5. Aba EVENTOS | C19: Log automático: toda resposta 'Não Conforme' na aba Checklists aparece aqui como um evento, trazendo observação, evidência (link/ID da foto), responsável, prazo e status. Inclui tabelas-resumo e gráficos (NCs por área, status e % de conformidade) que se atualizam sozinhos.

Sheet Checklists
A1: Código | B1: Área | C1: Referência | D1: Nº | E1: Item de Verificação | F1: Critério / O que verificar | G1: Resposta | H1: Observação | I1: Evidência (link/ID da foto) | J1: Responsável | K1: Prazo Correção | L1: Status | N1: aux
A2: ST-01 | B2: Segurança do Trabalho | C2: NR-01 – Gerenciamento de Riscos (GRO/PGR) | N2: =IF($G2="Não Conforme",COUNTIF($G$2:$G2,"Não Conforme"),"")
A3: ST-01 | B3: Segurança do Trabalho | C3: NR-01 – Gerenciamento de Riscos (GRO/PGR) | D3: 1 | E3: APR disponível na frente de serviço | F3: APR impressa/digital acessível no local da atividade | L3: Aberto | N3: =IF($G3="Não Conforme",COUNTIF($G$2:$G3,"Não Conforme"),"")
A4: ST-01 | B4: Segurança do Trabalho | C4: NR-01 – Gerenciamento de Riscos (GRO/PGR) | D4: 2 | E4: APR assinada por todos os executantes | F4: Assinaturas de toda a equipe e do responsável | L4: Aberto | N4: =IF($G4="Não Conforme",COUNTIF($G$2:$G4,"Não Conforme"),"")
A5: ST-01 | B5: Segurança do Trabalho | C5: NR-01 – Gerenciamento de Riscos (GRO/PGR) | D5: 3 | E5: APR compatível com a atividade real | F5: Riscos e etapas descritos correspondem ao que está sendo executado | L5: Aberto | N5: =IF($G5="Não Conforme",COUNTIF($G$2:$G5,"Não Conforme"),"")
A6: ST-01 | B6: Segurança do Trabalho | C6: NR-01 – Gerenciamento de Riscos (GRO/PGR) | D6: 4 | E6: DDS realizado e registrado | F6: Registro diário com tema, lista de presença e assinaturas | L6: Aberto | N6: =IF($G6="Não Conforme",COUNTIF($G$2:$G6,"Não Conforme"),"")
A7: ST-01 | B7: Segurança do Trabalho | C7: NR-01 – Gerenciamento de Riscos (GRO/PGR) | D7: 5 | E7: Permissão de Trabalho (PT) emitida | F7: PT válida para atividades especiais (altura, quente, elétrica, confinado) | L7: Aberto | N7: =IF($G7="Não Conforme",COUNTIF($G$2:$G7,"Não Conforme"),"")
A8: ST-01 | B8: Segurança do Trabalho | C8: NR-01 – Gerenciamento de Riscos (GRO/PGR) | D8: 6 | E8: Equipe treinada para a atividade | F8: Certificados válidos das NRs aplicáveis | L8: Aberto | N8: =IF($G8="Não Conforme",COUNTIF($G$2:$G8,"Não Conforme"),"")
A9: ST-01 | B9: Segurança do Trabalho | C9: NR-01 – Gerenciamento de Riscos (GRO/PGR) | D9: 7 | E9: Trabalhadores formalmente autorizados | F9: Autorização documentada (ex.: NR-10, NR-35) | L9: Aberto | N9: =IF($G9="Não Conforme",COUNTIF($G$2:$G9,"Não Conforme"),"")
A10: ST-01 | B10: Segurança do Trabalho | C10: NR-01 – Gerenciamento de Riscos (GRO/PGR) | D10: 8 | E10: Ferramentas e equipamentos inspecionados | F10: Checklist pré-uso preenchido, itens reprovados segregados | L10: Aberto | N10: =IF($G10="Não Conforme",COUNTIF($G$2:$G10,"Não Conforme"),"")
A11: ST-01 | B11: Segurança do Trabalho | C11: NR-01 – Gerenciamento de Riscos (GRO/PGR) | D11: 9 | E11: Riscos comunicados à equipe | F11: Trabalhadores sabem descrever os riscos e controles da tarefa | L11: Aberto | N11: =IF($G11="Não Conforme",COUNTIF($G$2:$G11,"Não Conforme"),"")
A12: ST-01 | B12: Segurança do Trabalho | C12: NR-01 – Gerenciamento de Riscos (GRO/PGR) | D12: 10 | E12: Medidas de controle implantadas | F12: Hierarquia de controles aplicada (eliminação → EPI) | L12: Aberto | N12: =IF($G12="Não Conforme",COUNTIF($G$2:$G12,"Não Conforme"),"")
A13: ST-01 | B13: Segurança do Trabalho | C13: NR-01 – Gerenciamento de Riscos (GRO/PGR) | D13: 11 | E13: Mudanças na atividade reavaliadas | F13: Alteração de escopo gerou revisão da APR/PT | L13: Aberto | N13: =IF($G13="Não Conforme",COUNTIF($G$2:$G13,"Não Conforme"),"")
A14: ST-01 | B14: Segurança do Trabalho | C14: NR-01 – Gerenciamento de Riscos (GRO/PGR) | D14: 12 | E14: PGR do canteiro atualizado | F14: Inventário de riscos e plano de ação vigentes | L14: Aberto | N14: =IF($G14="Não Conforme",COUNTIF($G$2:$G14,"Não Conforme"),"")
A15: ST-02 | B15: Segurança do Trabalho | C15: NR-06 – Equipamentos de Proteção Individual | N15: =IF($G15="Não Conforme",COUNTIF($G$2:$G15,"Não Conforme"),"")
A16: ST-02 | B16: Segurança do Trabalho | C16: NR-06 – Equipamentos de Proteção Individual | D16: 1 | E16: Capacete com jugular | F16: Uso correto, jugular ajustada em altura/içamento | L16: Aberto | N16: =IF($G16="Não Conforme",COUNTIF($G$2:$G16,"Não Conforme"),"")
A17: ST-02 | B17: Segurança do Trabalho | C17: NR-06 – Equipamentos de Proteção Individual | D17: 2 | E17: Óculos de proteção | F17: Compatível com o risco (impacto, UV, respingo) | L17: Aberto | N17: =IF($G17="Não Conforme",COUNTIF($G$2:$G17,"Não Conforme"),"")
A18: ST-02 | B18: Segurança do Trabalho | C18: NR-06 – Equipamentos de Proteção Individual | D18: 3 | E18: Botina de segurança | F18: Biqueira adequada, solado íntegro | L18: Aberto | N18: =IF($G18="Não Conforme",COUNTIF($G$2:$G18,"Não Conforme"),"")
A19: ST-02 | B19: Segurança do Trabalho | C19: NR-06 – Equipamentos de Proteção Individual | D19: 4 | E19: Vestimenta adequada | F19: Manga longa, uniforme íntegro; antichama onde exigido | L19: Aberto | N19: =IF($G19="Não Conforme",COUNTIF($G$2:$G19,"Não Conforme"),"")
A20: ST-02 | B20: Segurança do Trabalho | C20: NR-06 – Equipamentos de Proteção Individual | D20: 5 | E20: Luva correta para a tarefa | F20: Tipo compatível: mecânica, isolante, química, corte | L20: Aberto | N20: =IF($G20="Não Conforme",COUNTIF($G$2:$G20,"Não Conforme"),"")
A21: ST-02 | B21: Segurança do Trabalho | C21: NR-06 – Equipamentos de Proteção Individual | D21: 6 | E21: Protetor auricular | F21: Uso em áreas com ruído ≥ 85 dB(A) | L21: Aberto | N21: =IF($G21="Não Conforme",COUNTIF($G$2:$G21,"Não Conforme"),"")
A22: ST-02 | B22: Segurança do Trabalho | C22: NR-06 – Equipamentos de Proteção Individual | D22: 7 | E22: Protetor solar disponível e em uso | F22: Atividades a céu aberto (NR-21) | L22: Aberto | N22: =IF($G22="Não Conforme",COUNTIF($G$2:$G22,"Não Conforme"),"")
A23: ST-02 | B23: Segurança do Trabalho | C23: NR-06 – Equipamentos de Proteção Individual | D23: 8 | E23: Colete refletivo | F23: Áreas com tráfego de veículos/máquinas | L23: Aberto | N23: =IF($G23="Não Conforme",COUNTIF($G$2:$G23,"Não Conforme"),"")
A24: ST-02 | B24: Segurança do Trabalho | C24: NR-06 – Equipamentos de Proteção Individual | D24: 9 | E24: Proteção respiratória | F24: Máscara correta para poeira/fumos, com PPR quando aplicável | L24: Aberto | N24: =IF($G24="Não Conforme",COUNTIF($G$2:$G24,"Não Conforme"),"")
A25: ST-02 | B25: Segurança do Trabalho | C25: NR-06 – Equipamentos de Proteção Individual | D25: 10 | E25: Cinturão tipo paraquedista | F25: Trabalho em altura, íntegro e inspecionado | L25: Aberto | N25: =IF($G25="Não Conforme",COUNTIF($G$2:$G25,"Não Conforme"),"")
A26: ST-02 | B26: Segurança do Trabalho | C26: NR-06 – Equipamentos de Proteção Individual | D26: 11 | E26: Talabarte e absorvedor de energia | F26: Compatíveis com o plano de ancoragem | L26: Aberto | N26: =IF($G26="Não Conforme",COUNTIF($G$2:$G26,"Não Conforme"),"")
A27: ST-02 | B27: Segurança do Trabalho | C27: NR-06 – Equipamentos de Proteção Individual | D27: 12 | E27: Estado geral dos EPIs | F27: Sem danos, higienizados, dentro da vida útil | L27: Aberto | N27: =IF($G27="Não Conforme",COUNTIF($G$2:$G27,"Não Conforme"),"")
... A29: ST-02 | B29: Segurança do Trabalho | C29: NR-06 – Equipamentos de Proteção Individual | D29: 14 | E29: Registro de entrega de EPI | F29: Ficha de EPI assinada e atualizada | L29: Aberto | N29: =IF($G29="Não Conforme",COUNTIF($G$2:$G29,"Não Conforme"),"")
A30: ST-03 | B30: Segurança do Trabalho | C30: NR-10 – Instalações e Serviços em Eletricidade | N30: =IF($G30="Não Conforme",COUNTIF($G$2:$G30,"Não Conforme"),"")
A31: ST-03 | B31: Segurança do Trabalho | C31: NR-10 – Instalações e Serviços em Eletricidade | D31: 1 | E31: Painéis e circuitos identificados | F31: Identificação legível de painéis, disjuntores e circuitos | L31: Aberto | N31: =IF($G31="Não Conforme",COUNTIF($G$2:$G31,"Não Conforme"),"")
A32: ST-03 | B32: Segurança do Trabalho | C32: NR-10 – Instalações e Serviços em Eletricidade | D32: 2 | E32: Bloqueio e etiquetagem (LOTO) | F32: Cadeados individuais e etiquetas aplicados nas fontes de energia | L32: Aberto | N32: =IF($G32="Não Conforme",COUNTIF($G$2:$G32,"Não Conforme"),"")
A33: ST-03 | B33: Segurança do Trabalho | C33: NR-10 – Instalações e Serviços em Eletricidade | D33: 3 | E33: Ausência de tensão verificada | F33: Teste com detector antes do início dos serviços | L33: Aberto | N33: =IF($G33="Não Conforme",COUNTIF($G$2:$G33,"Não Conforme"),"")
A34: ST-03 | B34: Segurança do Trabalho | C34: NR-10 – Instalações e Serviços em Eletricidade | D34: 4 | E34: Aterramento temporário instalado | F34: Conjunto de aterramento aplicado conforme procedimento | L34: Aberto | N34: =IF($G34="Não Conforme",COUNTIF($G$2:$G34,"Não Conforme"),"")
A35: ST-03 | B35: Segurança do Trabalho | C35: NR-10 – Instalações e Serviços em Eletricidade | D35: 5 | E35: Isolamento e barreiras | F35: Partes vivas isoladas/sinalizadas, distâncias de segurança | L35: Aberto | N35: =IF($G35="Não Conforme",COUNTIF($G$2:$G35,"Não Conforme"),"")
A36: ST-03 | B36: Segurança do Trabalho | C36: NR-10 – Instalações e Serviços em Eletricidade | D36: 6 | E36: Ferramentas isoladas | F36: Ferramental com isolação íntegra e certificada | L36: Aberto | N36: =IF($G36="Não Conforme",COUNTIF($G$2:$G36,"Não Conforme"),"")
A37: ST-03 | B37: Segurança do Trabalho | C37: NR-10 – Instalações e Serviços em Eletricidade | D37: 7 | E37: Extintor adequado disponível | F37: CO2 ou pó BC próximo à atividade | L37: Aberto | N37: =IF($G37="Não Conforme",COUNTIF($G$2:$G37,"Não Conforme"),"")
A38: ST-03 | B38: Segurança do Trabalho | C38: NR-10 – Instalações e Serviços em Eletricidade | D38: 8 | E38: Área sinalizada e delimitada | F38: Isolamento físico e placas de advertência | L38: Aberto | N38: =IF($G38="Não Conforme",COUNTIF($G$2:$G38,"Não Conforme"),"")
A39: ST-03 | B39: Segurança do Trabalho | C39: NR-10 – Instalações e Serviços em Eletricidade | D39: 9 | E39: Profissionais autorizados | F39: Autorização formal + treinamento NR-10 (e SEP quando aplicável) | L39: Aberto | N39: =IF($G39="Não Conforme",COUNTIF($G$2:$G39,"Não Conforme"),"")
A40: ST-03 | B40: Segurança do Trabalho | C40: NR-10 – Instalações e Serviços em Eletricidade | D40: 10 | E40: Vestimenta antichama (arco elétrico) | F40: ATPV compatível com o estudo de arco/categoria de risco | L40: Aberto | N40: =IF($G40="Não Conforme",COUNTIF($G$2:$G40,"Não Conforme"),"")
A41: ST-03 | B41: Segurança do Trabalho | C41: NR-10 – Instalações e Serviços em Eletricidade | D41: 11 | E41: Prontuário das Instalações Elétricas (PIE) | F41: Atualizado e disponível | L41: Aberto | N41: =IF($G41="Não Conforme",COUNTIF($G$2:$G41,"Não Conforme"),"")
...

Sheet Cronograma
A1: Código | B1: Inspeção | C1: Frequência | D1: Seg | E1: Ter | F1: Qua | G1: Qui | H1: Sex | I1: Sáb | J1: Duração Estimada | K1: Responsável Sugerido
A2: ST-01 | B2: NR-01 APR/PT/DDS (ronda de campo) | C2: Diária | D2: X | E2: X | F2: X | G2: X | H2: X | I2: X | J2: 30 min | K2: Téc. Segurança
A3: ST-10 | B3: Ordem e Limpeza (ronda) | C3: Diária | D3: X | E3: X | F3: X | G3: X | H3: X | I3: X | J3: 20 min | K3: Encarregado / Téc. Segurança
A4: ST-06 | B4: NR-18 Canteiro de Obras (completo) | C4: Semanal | D4: X | J4: 1h30 | K4: Téc. Segurança + Fiscal
A5: VE-01 | B5: Veículos | C5: Semanal | D5: X | J5: 45 min | K5: Adm. / Téc. Segurança
A6: ST-02 | B6: NR-06 EPI (inspeção formal) | C6: Semanal | E6: X | J6: 45 min | K6: Téc. Segurança
A7: ST-08 | B7: NR-35 Trabalho em Altura | C7: Semanal | E7: X | J7: 1h | K7: Téc. Segurança
A8: ST-03 | B8: NR-10 Elétrica | C8: Semanal | F8: X | J8: 1h | K8: Fiscal Elétrica
A9: MA-01 | B9: Resíduos | C9: Semanal | F9: X | J9: 45 min | K9: Analista Ambiental
A10: MA-02 | B10: Solo e Contaminação | C10: Semanal | F10: X | J10: 30 min | K10: Analista Ambiental
A11: QA-01 | B11: Qualidade – Materiais | C11: Semanal | G11: X | J11: 45 min | K11: Fiscal Qualidade
A12: QA-02 | B12: Qualidade – Execução | C12: Semanal | G12: X | J12: 1h30 | K12: Fiscal Qualidade
A13: EQ-01 | B13: Equipamentos | C13: Semanal | G13: X | J13: 1h | K13: Fiscal Mecânica
A14: ST-05 | B14: NR-12 Máquinas | C14: Semanal | G14: X | J14: 45 min | K14: Téc. Segurança
A15: ST-04 | B15: NR-11 Içamento | C15: Semanal | H15: X | J15: 1h | K15: Fiscal + Téc. Segurança
A16: PR-01 | B16: Produção | C16: Semanal | H16: X | J16: 1h | K16: Fiscal de Contrato
A17: ST-09 | B17: NR-26 Sinalização | C17: Semanal | H17: X | J17: 30 min | K17: Téc. Segurança
A18: MA-03 | B18: Recursos Hídricos e Drenagem | C18: Quinzenal | E18: X | J18: 45 min | K18: Analista Ambiental
A19: MA-04 | B19: Flora, Fauna e Emissões | C19: Quinzenal | H19: X | J19: 45 min | K19: Analista Ambiental
A20: CT-01 | B20: Contratadas | C20: Quinzenal | D20: X | J20: 1h | K20: Fiscal de Contrato
A21: ST-11 | B21: NR-17 Ergonomia | C21: Mensal | F21: X | J21: 45 min | K21: Téc. Segurança
A22: ST-12 | B22: NR-20 Inflamáveis | C22: Mensal | F22: X | J22: 45 min | K22: Téc. Segurança
A23: SO-01 | B23: Saúde Ocupacional | C23: Mensal | E23: X | J23: 1h | K23: Téc. Segurança / Enfermagem
A24: EM-01 | B24: Emergência | C24: Mensal | G24: X | J24: 1h | K24: Téc. Segurança + Brigada
A25: DC-01 | B25: Documentação | C25: Mensal | H25: X | J25: 2h | K25: Adm. Contrato + Segurança
A26: ST-07 | B26: NR-33 Espaço Confinado | C26: Por evento | D26: — | E26: — | F26: — | G26: — | H26: — | I26: — | J26: antes de cada entrada | K26: Supervisor de Entrada
A27: ST-13 | B27: Trabalho a Quente | C27: Por evento | D27: — | E27: — | F27: — | G27: — | H27: — | I27: — | J27: antes de cada PT | K27: Téc. Segurança
A28: ST-14 | B28: Escavações | C28: Por evento + diária c/ frente ativa | D28: — | E28: — | F28: — | G28: — | H28: — | I28: — | J28: 20 min | K28: Fiscal Civil
A30: Notas:
A31: • | B31: Inspeções diárias (ST-01 e ST-10) são rondas rápidas; o registro pode ser simplificado (só desvios).
A32: • | B32: Inspeções 'Por evento' (NR-33, Trabalho a Quente, Escavações) são executadas na emissão da PT / abertura da frente, além de reavaliação diária enquanto a frente estiver ativa.
A33: • | B33: Quinzenais: alternar semanas A e B. Mensais: fixar na 1ª semana do mês para consolidar KPIs até o dia 5.
A34: • | B34: Sábado: aplicar apenas as rondas diárias se houver trabalho programado.

Sheet KPIs
A1: Categoria | B1: Indicador | C1: Fórmula / Regra de Cálculo | D1: Fonte de Dados | E1: Frequência | F1: Meta Sugerida
A2: Segurança | B2: HHT (Homem-Hora Trabalhada) | C2: Σ horas trabalhadas de todo o efetivo (próprio + contratadas) | D2: Folha de ponto / efetivo | E2: Mensal | F2: —
A3: Segurança | B3: Taxa de Frequência (TF) | C3: (Nº acidentes c/ afastamento × 1.000.000) ÷ HHT | D3: CATs + HHT | E3: Mensal | F3: < 5
A4: Segurança | B4: Taxa de Gravidade (TG) | C4: (Dias perdidos + debitados × 1.000.000) ÷ HHT | D4: CATs + HHT | E4: Mensal | F4: < 100
A5: Segurança | B5: % Conformidade Geral | C5: Itens Conformes ÷ (Conformes + Não Conformes) × 100 | D5: Formulários de inspeção | E5: Semanal | F5: ≥ 95%
A6: Segurança | B6: Nº de Não Conformidades | C6: Contagem de respostas 'Não Conforme' | D6: Formulários de inspeção | E6: Semanal | F6: Tendência ↓
A7: Segurança | B7: Nº de Condições Inseguras | C7: Registros classificados como condição | D7: Inspeções + relatos | E7: Semanal | F7: —
A8: Segurança | B8: Nº de Atos Inseguros | C8: Registros classificados como ato | D8: Inspeções + observações | E8: Semanal | F8: —
A9: Segurança | B9: Nº de Quase Acidentes | C9: Relatos de near miss | D9: Programa de relatos | E9: Mensal | F9: Tendência ↑ (relato)
A10: Segurança | B10: % Inspeções Realizadas | C10: Realizadas ÷ Planejadas × 100 | D10: Cronograma × registros | E10: Semanal | F10: ≥ 90%
A11: Segurança | B11: Tempo Médio de Fechamento de NC | C11: Σ (data fechamento − data abertura) ÷ nº NCs fechadas | D11: Formulários (Prazo/Status) | E11: Mensal | F11: ≤ 7 dias
A12: Segurança | B12: % Ações Corretivas no Prazo | C12: Fechadas dentro do prazo ÷ total fechadas × 100 | D12: Formulários (Prazo/Status) | E12: Mensal | F12: ≥ 90%
... A38: Gestão | B38: Pareto de Causas de NC | C38: 80/20 das causas-raiz | D38: Análise de causas | E38: Mensal | F38: Visual

Sheet Eventos
A1: REGISTRO DE EVENTOS – NÃO CONFORMIDADES (preenchido automaticamente a partir da aba Checklists)
A3: Nº | B3: Código | C3: Área | D3: Item | E3: Observação | F3: Evidência | G3: Responsável | H3: Prazo | I3: Status | M3: NCs por Área | P3: Status das NCs
A4: =IF($K4="","",ROWS($K$4:$K4)) | B4: =IF($K4="","",IF(INDEX(Checklists!$A:$A,$K4)="","",INDEX(Checklists!$A:$A,$K4))) | C4: =IF($K4="","",IF(INDEX(Checklists!$B:$B,$K4)="","",INDEX(Checklists!$B:$B,$K4))) | D4: =IF($K4="","",IF(INDEX(Checklists!$E:$E,$K4)="","",INDEX(Checklists!$E:$E,$K4))) | E4: =IF($K4="","",IF(INDEX(Checklists!$H:$H,$K4)="","",INDEX(Checklists!$H:$H,$K4))) | F4: =IF($K4="","",IF(INDEX(Checklists!$I:$I,$K4)="","",INDEX(Checklists!$I:$I,$K4))) | G4: =IF($K4="","",IF(INDEX(Checklists!$J:$J,$K4)="","",INDEX(Checklists!$J:$J,$K4))) | H4: =IF($K4="","",IF(INDEX(Checklists!$K:$K,$K4)="","",INDEX(Checklists!$K:$K,$K4))) | I4: =IF($K4="","",IF(INDEX(Checklists!$L:$L,$K4)="","",INDEX(Checklists!$L:$L,$K4))) | K4: =IFERROR(MATCH(ROWS($K$4:$K4),Checklists!$N$2:$N$291,0)+1,"") | M4: Área | N4: NCs | P4: Status | Q4: Qtde
A5: =IF($K5="","",ROWS($K$4:$K5)) | B5: =IF($K5="","",IF(INDEX(Checklists!$A:$A,$K5)="","",INDEX(Checklists!$A:$A,$K5))) | C5: =IF($K5="","",IF(INDEX(Checklists!$B:$B,$K5)="","",INDEX(Checklists!$B:$B,$K5))) | D5: =IF($K5="","",IF(INDEX(Checklists!$E:$E,$K5)="","",INDEX(Checklists!$E:$E,$K5))) | E5: =IF($K5="","",IF(INDEX(Checklists!$H:$H,$K5)="","",INDEX(Checklists!$H:$H,$K5))) | F5: =IF($K5="","",IF(INDEX(Checklists!$I:$I,$K5)="","",INDEX(Checklists!$I:$I,$K5))) | G5: =IF($K5="","",IF(INDEX(Checklists!$J:$J,$K5)="","",INDEX(Checklists!$J:$J,$K5))) | H5: =IF($K5="","",IF(INDEX(Checklists!$K:$K,$K5)="","",INDEX(Checklists!$K:$K,$K5))) | I5: =IF($K5="","",IF(INDEX(Checklists!$L:$L,$K5)="","",INDEX(Checklists!$L:$L,$K5))) | K5: =IFERROR(MATCH(ROWS($K$4:$K5),Checklists!$N$2:$N$291,0)+1,"") | M5: Segurança do Trabalho | N5: =COUNTIFS(Checklists!$B:$B,$M5,Checklists!$G:$G,"Não Conforme") -> 0 | P5: Aberto | Q5: =COUNTIFS(Checklists!$G:$G,"Não Conforme",Checklists!$L:$L,$P5) -> 0
A6: =IF($K6="","",ROWS($K$4:$K6)) | B6: =IF($K6="","",IF(INDEX(Checklists!$A:$A,$K6)="","",INDEX(Checklists!$A:$A,$K6))) | C6: =IF($K6="","",IF(INDEX(Checklists!$B:$B,$K6)="","",INDEX(Checklists!$B:$B,$K6))) | D6: =IF($K6="","",IF(INDEX(Checklists!$E:$E,$K6)="","",INDEX(Checklists!$E:$E,$K6))) | E6: =IF($K6="","",IF(INDEX(Checklists!$H:$H,$K6)="","",INDEX(Checklists!$H:$H,$K6))) | F6: =IF($K6="","",IF(INDEX(Checklists!$I:$I,$K6)="","",INDEX(Checklists!$I:$I,$K6))) | G6: =IF($K6="","",IF(INDEX(Checklists!$J:$J,$K6)="","",INDEX(Checklists!$J:$J,$K6))) | H6: =IF($K6="","",IF(INDEX(Checklists!$K:$K,$K6)="","",INDEX(Checklists!$K:$K,$K6))) | I6: =IF($K6="","",IF(INDEX(Checklists!$L:$L,$K6)="","",INDEX(Checklists!$L:$L,$K6))) | K6: =IFERROR(MATCH(ROWS($K$4:$K6),Checklists!$N$2:$N$291,0)+1,"") | M6: Meio Ambiente | N6: =COUNTIFS(Checklists!$B:$B,$M6,Checklists!$G:$G,"Não Conforme") -> 0 | P6: Em Andamento | Q6: =COUNTIFS(Checklists!$G:$G,"Não Conforme",Checklists!$L:$L,$P6) -> 0
A7: =IF($K7="","",ROWS($K$4:$K7)) | B7: =IF($K7="","",IF(INDEX(Checklists!$A:$A,$K7)="","",INDEX(Checklists!$A:$A,$K7))) | C7: =IF($K7="","",IF(INDEX(Checklists!$B:$B,$K7)="","",INDEX(Checklists!$B:$B,$K7))) | D7: =IF($K7="","",IF(INDEX(Checklists!$E:$E,$K7)="","",INDEX(Checklists!$E:$E,$K7))) | E7: =IF($K7="","",IF(INDEX(Checklists!$H:$H,$K7)="","",INDEX(Checklists!$H:$H,$K7))) | F7: =IF($K7="","",IF(INDEX(Checklists!$I:$I,$K7)="","",INDEX(Checklists!$I:$I,$K7))) | G7: =IF($K7="","",IF(INDEX(Checklists!$J:$J,$K7)="","",INDEX(Checklists!$J:$J,$K7))) | H7: =IF($K7="","",IF(INDEX(Checklists!$K:$K,$K7)="","",INDEX(Checklists!$K:$K,$K7))) | I7: =IF($K7="","",IF(INDEX(Checklists!$L:$L,$K7)="","",INDEX(Checklists!$L:$L,$K7))) | K7: =IFERROR(MATCH(ROWS($K$4:$K7),Checklists!$N$2:$N$291,0)+1,"") | M7: Qualidade | N7: =COUNTIFS(Checklists!$B:$B,$M7,Checklists!$G:$G,"Não Conforme") -> 0 | P7: Fechado | Q7: =COUNTIFS(Checklists!$G:$G,"Não Conforme",Checklists!$L:$L,$P7) -> 0
A8: =IF($K8="","",ROWS($K$4:$K8)) | B8: =IF($K8="","",IF(INDEX(Checklists!$A:$A,$K8)="","",INDEX(Checklists!$A:$A,$K8))) | C8: =IF($K8="","",IF(INDEX(Checklists!$B:$B,$K8)="","",INDEX(Checklists!$B:$B,$K8))) | D8: =IF($K8="","",IF(INDEX(Checklists!$E:$E,$K8)="","",INDEX(Checklists!$E:$E,$K8))) | E8: =IF($K8="","",IF(INDEX(Checklists!$H:$H,$K8)="","",INDEX(Checklists!$H:$H,$K8))) | F8: =IF($K8="","",IF(INDEX(Checklists!$I:$I,$K8)="","",INDEX(Checklists!$I:$I,$K8))) | G8: =IF($K8="","",IF(INDEX(Checklists!$J:$J,$K8)="","",INDEX(Checklists!$J:$J,$K8))) | H8: =IF($K8="","",IF(INDEX(Checklists!$K:$K,$K8)="","",INDEX(Checklists!$K:$K,$K8))) | I8: =IF($K8="","",IF(INDEX(Checklists!$L:$L,$K8)="","",INDEX(Checklists!$L:$L,$K8))) | K8: =IFERROR(MATCH(ROWS($K$4:$K8),Checklists!$N$2:$N$291,0)+1,"") | M8: Equipamentos | N8: =COUNTIFS(Checklists!$B:$B,$M8,Checklists!$G:$G,"Não Conforme") -> 0
A9: =IF($K9="","",ROWS($K$4:$K9)) | B9: =IF($K9="","",IF(INDEX(Checklists!$A:$A,$K9)="","",INDEX(Checklists!$A:$A,$K9))) | C9: =IF($K9="","",IF(INDEX(Checklists!$B:$B,$K9)="","",INDEX(Checklists!$B:$B,$K9))) | D9: =IF($K9="","",IF(INDEX(Checklists!$E:$E,$K9)="","",INDEX(Checklists!$E:$E,$K9))) | E9: =IF($K9="","",IF(INDEX(Checklists!$H:$H,$K9)="","",INDEX(Checklists!$H:$H,$K9))) | F9: =IF($K9="","",IF(INDEX(Checklists!$I:$I,$K9)="","",INDEX(Checklists!$I:$I,$K9))) | G9: =IF($K9="","",IF(INDEX(Checklists!$J:$J,$K9)="","",INDEX(Checklists!$J:$J,$K9))) | H9: =IF($K9="","",IF(INDEX(Checklists!$K:$K,$K9)="","",INDEX(Checklists!$K:$K,$K9))) | I9: =IF($K9="","",IF(INDEX(Checklists!$L:$L,$K9)="","",INDEX(Checklists!$L:$L,$K9))) | K9: =IFERROR(MATCH(ROWS($K$4:$K9),Checklists!$N$2:$N$291,0)+1,"") | M9: Documentação | N9: =COUNTIFS(Checklists!$B:$B,$M9,Checklists!$G:$G,"Não Conforme") -> 0 | P9: Total de NCs | Q9: =COUNTIFS(Checklists!$G:$G,"Não Conforme") -> 0
A10: =IF($K10="","",ROWS($K$4:$K10)) | B10: =IF($K10="","",IF(INDEX(Checklists!$A:$A,$K10)="","",INDEX(Checklists!$A:$A,$K10))) | C10: =IF($K10="","",IF(INDEX(Checklists!$B:$B,$K10)="","",INDEX(Checklists!$B:$B,$K10))) | D10: =IF($K10="","",IF(INDEX(Checklists!$E:$E,$K10)="","",INDEX(Checklists!$E:$E,$K10))) | E10: =IF($K10="","",IF(INDEX(Checklists!$H:$H,$K10)="","",INDEX(Checklists!$H:$H,$K10))) | F10: =IF($K10="","",IF(INDEX(Checklists!$I:$I,$K10)="","",INDEX(Checklists!$I:$I,$K10))) | G10: =IF($K10="","",IF(INDEX(Checklists!$J:$J,$K10)="","",INDEX(Checklists!$J:$J,$K10))) | H10: =IF($K10="","",IF(INDEX(Checklists!$K:$K,$K10)="","",INDEX(Checklists!$K:$K,$K10))) | I10: =IF($K10="","",IF(INDEX(Checklists!$L:$L,$K10)="","",INDEX(Checklists!$L:$L,$K10))) | K10: =IFERROR(MATCH(ROWS($K$4:$K10),Checklists!$N$2:$N$291,0)+1,"") | M10: Veículos | N10: =COUNTIFS(Checklists!$B:$B,$M10,Checklists!$G:$G,"Não Conforme") -> 0 | P10: NCs c/ Evidência | Q10: =COUNTIFS(Checklists!$G:$G,"Não Conforme",Checklists!$I:$I,"<>") -> 0
A11: =IF($K11="","",ROWS($K$4:$K11)) | B11: =IF($K11="","",IF(INDEX(Checklists!$A:$A,$K11)="","",INDEX(Checklists!$A:$A,$K11))) | C11: =IF($K11="","",IF(INDEX(Checklists!$B:$B,$K11)="","",INDEX(Checklists!$B:$B,$K11))) | D11: =IF($K11="","",IF(INDEX(Checklists!$E:$E,$K11)="","",INDEX(Checklists!$E:$E,$K11))) | E11: =IF($K11="","",IF(INDEX(Checklists!$H:$H,$K11)="","",INDEX(Checklists!$H:$H,$K11))) | F11: =IF($K11="","",IF(INDEX(Checklists!$I:$I,$K11)="","",INDEX(Checklists!$I:$I,$K11))) | G11: =IF($K11="","",IF(INDEX(Checklists!$J:$J,$K11)="","",INDEX(Checklists!$J:$J,$K11))) | H11: =IF($K11="","",IF(INDEX(Checklists!$K:$K,$K11)="","",INDEX(Checklists!$K:$K,$K11))) | I11: =IF($K11="","",IF(INDEX(Checklists!$L:$L,$K11)="","",INDEX(Checklists!$L:$L,$K11))) | K11: =IFERROR(MATCH(ROWS($K$4:$K11),Checklists!$N$2:$N$291,0)+1,"") | M11: Saúde Ocupacional | N11: =COUNTIFS(Checklists!$B:$B,$M11,Checklists!$G:$G,"Não Conforme") -> 0
A12: =IF($K12="","",ROWS($K$4:$K12)) | B12: =IF($K12="","",IF(INDEX(Checklists!$A:$A,$K12)="","",INDEX(Checklists!$A:$A,$K12))) | C12: =IF($K12="","",IF(INDEX(Checklists!$B:$B,$K12)="","",INDEX(Checklists!$B:$B,$K12))) | D12: =IF($K12="","",IF(INDEX(Checklists!$E:$E,$K12)="","",INDEX(Checklists!$E:$E,$K12))) | E12: =IF($K12="","",IF(INDEX(Checklists!$H:$H,$K12)="","",INDEX(Checklists!$H:$H,$K12))) | F12: =IF($K12="","",IF(INDEX(Checklists!$I:$I,$K12)="","",INDEX(Checklists!$I:$I,$K12))) | G12: =IF($K12="","",IF(INDEX(Checklists!$J:$J,$K12)="","",INDEX(Checklists!$J:$J,$K12))) | H12: =IF($K12="","",IF(INDEX(Checklists!$K:$K,$K12)="","",INDEX(Checklists!$K:$K,$K12))) | I12: =IF($K12="","",IF(INDEX(Checklists!$L:$L,$K12)="","",INDEX(Checklists!$L:$L,$K12))) | K12: =IFERROR(MATCH(ROWS($K$4:$K12),Checklists!$N$2:$N$291,0)+1,"") | M12: Emergência | N12: =COUNTIFS(Checklists!$B:$B,$M12,Checklists!$G:$G,"Não Conforme") -> 0
A13: =IF($K13="","",ROWS($K$4:$K13)) | B13: =IF($K13="","",IF(INDEX(Checklists!$A:$A,$K13)="","",INDEX(Checklists!$A:$A,$K13))) | C13: =IF($K13="","",IF(INDEX(Checklists!$B:$B,$K13)="","",INDEX(Checklists!$B:$B,$K13))) | D13: =IF($K13="","",IF(INDEX(Checklists!$E:$E,$K13)="","",INDEX(Checklists!$E:$E,$K13))) | E13: =IF($K13="","",IF(INDEX(Checklists!$H:$H,$K13)="","",INDEX(Checklists!$H:$H,$K13))) | F13: =IF($K13="","",IF(INDEX(Checklists!$I:$I,$K13)="","",INDEX(Checklists!$I:$I,$K13))) | G13: =IF($K13="","",IF(INDEX(Checklists!$J:$J,$K13)="","",INDEX(Checklists!$J:$J,$K13))) | H13: =IF($K13="","",IF(INDEX(Checklists!$K:$K,$K13)="","",INDEX(Checklists!$K:$K,$K13))) | I13: =IF($K13="","",IF(INDEX(Checklists!$L:$L,$K13)="","",INDEX(Checklists!$L:$L,$K13))) | K13: =IFERROR(MATCH(ROWS($K$4:$K13),Checklists!$N$2:$N$291,0)+1,"") | M13: Contratadas | N13: =COUNTIFS(Checklists!$B:$B,$M13,Checklists!$G:$G,"Não Conforme") -> 0
A14: =IF($K14="","",ROWS($K$4:$K14)) | B14: =IF($K14="","",IF(INDEX(Checklists!$A:$A,$K14)="","",INDEX(Checklists!$A:$A,$K14))) | C14: =IF($K14="","",IF(INDEX(Checklists!$B:$B,$K14)="","",INDEX(Checklists!$B:$B,$K14))) | D14: =IF($K14="","",IF(INDEX(Checklists!$E:$E,$K14)="","",INDEX(Checklists!$E:$E,$K14))) | E14: =IF($K14="","",IF(INDEX(Checklists!$H:$H,$K14)="","",INDEX(Checklists!$H:$H,$K14))) | F14: =IF($K14="","",IF(INDEX(Checklists!$I:$I,$K14)="","",INDEX(Checklists!$I:$I,$K14))) | G14: =IF($K14="","",IF(INDEX(Checklists!$J:$J,$K14)="","",INDEX(Checklists!$J:$J,$K14))) | H14: =IF($K14="","",IF(INDEX(Checklists!$K:$K,$K14)="","",INDEX(Checklists!$K:$K,$K14))) | I14: =IF($K14="","",IF(INDEX(Checklists!$L:$L,$K14)="","",INDEX(Checklists!$L:$L,$K14))) | K14: =IFERROR(MATCH(ROWS($K$4:$K14),Checklists!$N$2:$N$291,0)+1,"") | M14: Produção | N14: =COUNTIFS(Checklists!$B:$B,$M14,Checklists!$G:$G,"Não Conforme") -> 0
A15: =IF($K15="","",ROWS($K$4:$K15)) | B15: =IF($K15="","",IF(INDEX(Checklists!$A:$A,$K15)="","",INDEX(Checklists!$A:$A,$K15))) | C15: =IF($K15="","",IF(INDEX(Checklists!$B:$B,$K15)="","",INDEX(Checklists!$B:$B,$K15))) | D15: =IF($K15="","",IF(INDEX(Checklists!$E:$E,$K15)="","",INDEX(Checklists!$E:$E,$K15))) | E15: =IF($K15="","",IF(INDEX(Checklists!$H:$H,$K15)="","",INDEX(Checklists!$H:$H,$K15))) | F15: =IF($K15="","",IF(INDEX(Checklists!$I:$I,$K15)="","",INDEX(Checklists!$I:$I,$K15))) | G15: =IF($K15="","",IF(INDEX(Checklists!$J:$J,$K15)="","",INDEX(Checklists!$J:$J,$K15))) | H15: =IF($K15="","",IF(INDEX(Checklists!$K:$K,$K15)="","",INDEX(Checklists!$K:$K,$K15))) | I15: =IF($K15="","",IF(INDEX(Checklists!$L:$L,$K15)="","",INDEX(Checklists!$L:$L,$K15))) | K15: =IFERROR(MATCH(ROWS($K$4:$K15),Checklists!$N$2:$N$291,0)+1,"")
A16: =IF($K16="","",ROWS($K$4:$K16)) | B16: =IF($K16="","",IF(INDEX(Checklists!$A:$A,$K16)="","",INDEX(Checklists!$A:$A,$K16))) | C16: =IF($K16="","",IF(INDEX(Checklists!$B:$B,$K16)="","",INDEX(Checklists!$B:$B,$K16))) | D16: =IF($K16="","",IF(INDEX(Checklists!$E:$E,$K16)="","",INDEX(Checklists!$E:$E,$K16))) | E16: =IF($K16="","",IF(INDEX(Checklists!$H:$H,$K16)="","",INDEX(Checklists!$H:$H,$K16))) | F16: =IF($K16="","",IF(INDEX(Checklists!$I:$I,$K16)="","",INDEX(Checklists!$I:$I,$K16))) | G16: =IF($K16="","",IF(INDEX(Checklists!$J:$J,$K16)="","",INDEX(Checklists!$J:$J,$K16))) | H16: =IF($K16="","",IF(INDEX(Checklists!$K:$K,$K16)="","",INDEX(Checklists!$K:$K,$K16))) | I16: =IF($K16="","",IF(INDEX(Checklists!$L:$L,$K16)="","",INDEX(Checklists!$L:$L,$K16))) | K16: =IFERROR(MATCH(ROWS($K$4:$K16),Checklists!$N$2:$N$291,0)+1,"")
A17: =IF($K17="","",ROWS($K$4:$K17)) | B17: =IF($K17="","",IF(INDEX(Checklists!$A:$A,$K17)="","",INDEX(Checklists!$A:$A,$K17))) | C17: =IF($K17="","",IF(INDEX(Checklists!$B:$B,$K17)="","",INDEX(Checklists!$B:$B,$K17))) | D17: =IF($K17="","",IF(INDEX(Checklists!$E:$E,$K17)="","",INDEX(Checklists!$E:$E,$K17))) | E17: =IF($K17="","",IF(INDEX(Checklists!$H:$H,$K17)="","",INDEX(Checklists!$H:$H,$K17))) | F17: =IF($K17="","",IF(INDEX(Checklists!$I:$I,$K17)="","",INDEX(Checklists!$I:$I,$K17))) | G17: =IF($K17="","",IF(INDEX(Checklists!$J:$J,$K17)="","",INDEX(Checklists!$J:$J,$K17))) | H17: =IF($K17="","",IF(INDEX(Checklists!$K:$K,$K17)="","",INDEX(Checklists!$K:$K,$K17))) | I17: =IF($K17="","",IF(INDEX(Checklists!$L:$L,$K17)="","",INDEX(Checklists!$L:$L,$K17))) | K17: =IFERROR(MATCH(ROWS($K$4:$K17),Checklists!$N$2:$N$291,0)+1,"") | M17: % Conformidade por Área
A18: =IF($K18="","",ROWS($K$4:$K18)) | B18: =IF($K18="","",IF(INDEX(Checklists!$A:$A,$K18)="","",INDEX(Checklists!$A:$A,$K18))) | C18: =IF($K18="","",IF(INDEX(Checklists!$B:$B,$K18)="","",INDEX(Checklists!$B:$B,$K18))) | D18: =IF($K18="","",IF(INDEX(Checklists!$E:$E,$K18)="","",INDEX(Checklists!$E:$E,$K18))) | E18: =IF($K18="","",IF(INDEX(Checklists!$H:$H,$K18)="","",INDEX(Checklists!$H:$H,$K18))) | F18: =IF($K18="","",IF(INDEX(Checklists!$I:$I,$K18)="","",INDEX(Checklists!$I:$I,$K18))) | G18: =IF($K18="","",IF(INDEX(Checklists!$J:$J,$K18)="","",INDEX(Checklists!$J:$J,$K18))) | H18: =IF($K18="","",IF(INDEX(Checklists!$K:$K,$K18)="","",INDEX(Checklists!$K:$K,$K18))) | I18: =IF($K18="","",IF(INDEX(Checklists!$L:$L,$K18)="","",INDEX(Checklists!$L:$L,$K18))) | K18: =IFERROR(MATCH(ROWS($K$4:$K18),Checklists!$N$2:$N$291,0)+1,"") | M18: Área | N18: Conf. | O18: NC | P18: % Conform.
A19: =IF($K19="","",ROWS($K$4:$K19)) | B19: =IF($K19="","",IF(INDEX(Checklists!$A:$A,$K19)="","",INDEX(Checklists!$A:$A,$K19))) | C19: =IF($K19="","",IF(INDEX(Checklists!$B:$B,$K19)="","",INDEX(Checklists!$B:$B,$K19))) | D19: =IF($K19="","",IF(INDEX(Checklists!$E:$E,$K19)="","",INDEX(Checklists!$E:$E,$K19))) | E19: =IF($K19="","",IF(INDEX(Checklists!$H:$H,$K19)="","",INDEX(Checklists!$H:$H,$K19))) | F19: =IF($K19="","",IF(INDEX(Checklists!$I:$I,$K19)="","",INDEX(Checklists!$I:$I,$K19))) | G19: =IF($K19="","",IF(INDEX(Checklists!$J:$J,$K19)="","",INDEX(Checklists!$J:$J,$K19))) | H19: =IF($K19="","",IF(INDEX(Checklists!$K:$K,$K19)="","",INDEX(Checklists!$K:$K,$K19))) | I19: =IF($K19="","",IF(INDEX(Checklists!$L:$L,$K19)="","",INDEX(Checklists!$L:$L,$K19))) | K19: =IFERROR(MATCH(ROWS($K$4:$K19),Checklists!$N$2:$N$291,0)+1,"") | M19: Segurança do Trabalho | N19: =COUNTIFS(Checklists!$B:$B,$M19,Checklists!$G:$G,"Conforme") -> 0 | O19: =COUNTIFS(Checklists!$B:$B,$M19,Checklists!$G:$G,"Não Conforme") -> 0 | P19: =IF($N19+$O19=0,"",$N19/($N19+$O19))
A20: =IF($K20="","",ROWS($K$4:$K20)) | B20: =IF($K20="","",IF(INDEX(Checklists!$A:$A,$K20)="","",INDEX(Checklists!$A:$A,$K20))) | C20: =IF($K20="","",IF(INDEX(Checklists!$B:$B,$K20)="","",INDEX(Checklists!$B:$B,$K20))) | D20: =IF($K20="","",IF(INDEX(Checklists!$E:$E,$K20)="","",INDEX(Checklists!$E:$E,$K20))) | E20: =IF($K20="","",IF(INDEX(Checklists!$H:$H,$K20)="","",INDEX(Checklists!$H:$H,$K20))) | F20: =IF($K20="","",IF(INDEX(Checklists!$I:$I,$K20)="","",INDEX(Checklists!$I:$I,$K20))) | G20: =IF($K20="","",IF(INDEX(Checklists!$J:$J,$K20)="","",INDEX(Checklists!$J:$J,$K20))) | H20: =IF($K20="","",IF(INDEX(Checklists!$K:$K,$K20)="","",INDEX(Checklists!$K:$K,$K20))) | I20: =IF($K20="","",IF(INDEX(Checklists!$L:$L,$K20)="","",INDEX(Checklists!$L:$L,$K20))) | K20: =IFERROR(MATCH(ROWS($K$4:$K20),Checklists!$N$2:$N$291,0)+1,"") | M20: Meio Ambiente | N20: =COUNTIFS(Checklists!$B:$B,$M20,Checklists!$G:$G,"Conforme") -> 0 | O20: =COUNTIFS(Checklists!$B:$B,$M20,Checklists!$G:$G,"Não Conforme") -> 0 | P20: =IF($N20+$O20=0,"",$N20/($N20+$O20))
A21: =IF($K21="","",ROWS($K$4:$K21)) | B21: =IF($K21="","",IF(INDEX(Checklists!$A:$A,$K21)="","",INDEX(Checklists!$A:$A,$K21))) | C21: =IF($K21="","",IF(INDEX(Checklists!$B:$B,$K21)="","",INDEX(Checklists!$B:$B,$K21))) | D21: =IF($K21="","",IF(INDEX(Checklists!$E:$E,$K21)="","",INDEX(Checklists!$E:$E,$K21))) | E21: =IF($K21="","",IF(INDEX(Checklists!$H:$H,$K21)="","",INDEX(Checklists!$H:$H,$K21))) | F21: =IF($K21="","",IF(INDEX(Checklists!$I:$I,$K21)="","",INDEX(Checklists!$I:$I,$K21))) | G21: =IF($K21="","",IF(INDEX(Checklists!$J:$J,$K21)="","",INDEX(Checklists!$J:$J,$K21))) | H21: =IF($K21="","",IF(INDEX(Checklists!$K:$K,$K21)="","",INDEX(Checklists!$K:$K,$K21))) | I21: =IF($K21="","",IF(INDEX(Checklists!$L:$L,$K21)="","",INDEX(Checklists!$L:$L,$K21))) | K21: =IFERROR(MATCH(ROWS($K$4:$K21),Checklists!$N$2:$N$291,0)+1,"") | M21: Qualidade | N21: =COUNTIFS(Checklists!$B:$B,$M21,Checklists!$G:$G,"Conforme") -> 0 | O21: =COUNTIFS(Checklists!$B:$B,$M21,Checklists!$G:$G,"Não Conforme") -> 0 | P21: =IF($N21+$O21=0,"",$N21/($N21+$O21))
A22: =IF($K22="","",ROWS($K$4:$K22)) | B22: =IF($K22="","",IF(INDEX(Checklists!$A:$A,$K22)="","",INDEX(Checklists!$A:$A,$K22))) | C22: =IF($K22="","",IF(INDEX(Checklists!$B:$B,$K22)="","",INDEX(Checklists!$B:$B,$K22))) | D22: =IF($K22="","",IF(INDEX(Checklists!$E:$E,$K22)="","",INDEX(Checklists!$E:$E,$K22))) | E22: =IF($K22="","",IF(INDEX(Checklists!$H:$H,$K22)="","",INDEX(Checklists!$H:$H,$K22))) | F22: =IF($K22="","",IF(INDEX(Checklists!$I:$I,$K22)="","",INDEX(Checklists!$I:$I,$K22))) | G22: =IF($K22="","",IF(INDEX(Checklists!$J:$J,$K22)="","",INDEX(Checklists!$J:$J,$K22))) | H22: =IF($K22="","",IF(INDEX(Checklists!$K:$K,$K22)="","",INDEX(Checklists!$K:$K,$K22))) | I22: =IF($K22="","",IF(INDEX(Checklists!$L:$L,$K22)="","",INDEX(Checklists!$L:$L,$K22))) | K22: =IFERROR(MATCH(ROWS($K$4:$K22),Checklists!$N$2:$N$291,0)+1,"") | M22: Equipamentos | N22: =COUNTIFS(Checklists!$B:$B,$M22,Checklists!$G:$G,"Conforme") -> 0 | O22: =COUNTIFS(Checklists!$B:$B,$M22,Checklists!$G:$G,"Não Conforme") -> 0 | P22: =IF($N22+$O22=0,"",$N22/($N22+$O22))
A23: =IF($K23="","",ROWS($K$4:$K23)) | B23: =IF($K23="","",IF(INDEX(Checklists!$A:$A,$K23)="","",INDEX(Checklists!$A:$A,$K23))) | C23: =IF($K23="","",IF(INDEX(Checklists!$B:$B,$K23)="","",INDEX(Checklists!$B:$B,$K23))) | D23: =IF($K23="","",IF(INDEX(Checklists!$E:$E,$K23)="","",INDEX(Checklists!$E:$E,$K23))) | E23: =IF($K23="","",IF(INDEX(Checklists!$H:$H,$K23)="","",INDEX(Checklists!$H:$H,$K23))) | F23: =IF($K23="","",IF(INDEX(Checklists!$I:$I,$K23)="","",INDEX(Checklists!$I:$I,$K23))) | G23: =IF($K23="","",IF(INDEX(Checklists!$J:$J,$K23)="","",INDEX(Checklists!$J:$J,$K23))) | H23: =IF($K23="","",IF(INDEX(Checklists!$K:$K,$K23)="","",INDEX(Checklists!$K:$K,$K23))) | I23: =IF($K23="","",IF(INDEX(Checklists!$L:$L,$K23)="","",INDEX(Checklists!$L:$L,$K23))) | K23: =IFERROR(MATCH(ROWS($K$4:$K23),Checklists!$N$2:$N$291,0)+1,"") | M23: Documentação | N23: =COUNTIFS(Checklists!$B:$B,$M23,Checklists!$G:$G,"Conforme") -> 0 | O23: =COUNTIFS(Checklists!$B:$B,$M23,Checklists!$G:$G,"Não Conforme") -> 0 | P23: =IF($N23+$O23=0,"",$N23/($N23+$O23))
A24: =IF($K24="","",ROWS($K$4:$K24)) | B24: =IF($K24="","",IF(INDEX(Checklists!$A:$A,$K24)="","",INDEX(Checklists!$A:$A,$K24))) | C24: =IF($K24="","",IF(INDEX(Checklists!$B:$B,$K24)="","",INDEX(Checklists!$B:$B,$K24))) | D24: =IF($K24="","",IF(INDEX(Checklists!$E:$E,$K24)="","",INDEX(Checklists!$E:$E,$K24))) | E24: =IF($K24="","",IF(INDEX(Checklists!$H:$H,$K24)="","",INDEX(Checklists!$H:$H,$K24))) | F24: =IF($K24="","",IF(INDEX(Checklists!$I:$I,$K24)="","",INDEX(Checklists!$I:$I,$K24))) | G24: =IF($K24="","",IF(INDEX(Checklists!$J:$J,$K24)="","",INDEX(Checklists!$J:$J,$K24))) | H24: =IF($K24="","",IF(INDEX(Checklists!$K:$K,$K24)="","",INDEX(Checklists!$K:$K,$K24))) | I24: =IF($K24="","",IF(INDEX(Checklists!$L:$L,$K24)="","",INDEX(Checklists!$L:$L,$K24))) | K24: =IFERROR(MATCH(ROWS($K$4:$K24),Checklists!$N$2:$N$291,0)+1,"") | M24: Veículos | N24: =COUNTIFS(Checklists!$B:$B,$M24,Checklists!$G:$G,"Conforme") -> 0 | O24: =COUNTIFS(Checklists!$B:$B,$M24,Checklists!$G:$G,"Não Conforme") -> 0 | P24: =IF($N24+$O24=0,"",$N24/($N24+$O24))
A25: =IF($K25="","",ROWS($K$4:$K25)) | B25: =IF($K25="","",IF(INDEX(Checklists!$A:$A,$K25)="","",INDEX(Checklists!$A:$A,$K25))) | C25: =IF($K25="","",IF(INDEX(Checklists!$B:$B,$K25)="","",INDEX(Checklists!$B:$B,$K25))) | D25: =IF($K25="","",IF(INDEX(Checklists!$E:$E,$K25)="","",INDEX(Checklists!$E:$E,$K25))) | E25: =IF($K25="","",IF(INDEX(Checklists!$H:$H,$K25)="","",INDEX(Checklists!$H:$H,$K25))) | F25: =IF($K25="","",IF(INDEX(Checklists!$I:$I,$K25)="","",INDEX(Checklists!$I:$I,$K25))) | G25: =IF($K25="","",IF(INDEX(Checklists!$J:$J,$K25)="","",INDEX(Checklists!$J:$J,$K25))) | H25: =IF($K25="","",IF(INDEX(Checklists!$K:$K,$K25)="","",INDEX(Checklists!$K:$K,$K25))) | I25: =IF($K25="","",IF(INDEX(Checklists!$L:$L,$K25)="","",INDEX(Checklists!$L:$L,$K25))) | K25: =IFERROR(MATCH(ROWS($K$4:$K25),Checklists!$N$2:$N$291,0)+1,"") | M25: Saúde Ocupacional | N25: =COUNTIFS(Checklists!$B:$B,$M25,Checklists!$G:$G,"Conforme") -> 0 | O25: =COUNTIFS(Checklists!$B:$B,$M25,Checklists!$G:$G,"Não Conforme") -> 0 | P25: =IF($N25+$O25=0,"",$N25/($N25+$O25))
A26: =IF($K26="","",ROWS($K$4:$K26)) | B26: =IF($K26="","",IF(INDEX(Checklists!$A:$A,$K26)="","",INDEX(Checklists!$A:$A,$K26))) | C26: =IF($K26="","",IF(INDEX(Checklists!$B:$B,$K26)="","",INDEX(Checklists!$B:$B,$K26))) | D26: =IF($K26="","",IF(INDEX(Checklists!$E:$E,$K26)="","",INDEX(Checklists!$E:$E,$K26))) | E26: =IF($K26="","",IF(INDEX(Checklists!$H:$H,$K26)="","",INDEX(Checklists!$H:$H,$K26))) | F26: =IF($K26="","",IF(INDEX(Checklists!$I:$I,$K26)="","",INDEX(Checklists!$I:$I,$K26))) | G26: =IF($K26="","",IF(INDEX(Checklists!$J:$J,$K26)="","",INDEX(Checklists!$J:$J,$K26))) | H26: =IF($K26="","",IF(INDEX(Checklists!$K:$K,$K26)="","",INDEX(Checklists!$K:$K,$K26))) | I26: =IF($K26="","",IF(INDEX(Checklists!$L:$L,$K26)="","",INDEX(Checklists!$L:$L,$K26))) | K26: =IFERROR(MATCH(ROWS($K$4:$K26),Checklists!$N$2:$N$291,0)+1,"") | M26: Emergência | N26: =COUNTIFS(Checklists!$B:$B,$M26,Checklists!$G:$G,"Conforme") -> 0 | O26: =COUNTIFS(Checklists!$B:$B,$M26,Checklists!$G:$G,"Não Conforme") -> 0 | P26: =IF($N26+$O26=0,"",$N26/($N26+$O26))
A27: =IF($K27="","",ROWS($K$4:$K27)) | B27: =IF($K27="","",IF(INDEX(Checklists!$A:$A,$K27)="","",INDEX(Checklists!$A:$A,$K27))) | C27: =IF($K27="","",IF(INDEX(Checklists!$B:$B,$K27)="","",INDEX(Checklists!$B:$B,$K27))) | D27: =IF($K27="","",IF(INDEX(Checklists!$E:$E,$K27)="","",INDEX(Checklists!$E:$E,$K27))) | E27: =IF($K27="","",IF(INDEX(Checklists!$H:$H,$K27)="","",INDEX(Checklists!$H:$H,$K27))) | F27: =IF($K27="","",IF(INDEX(Checklists!$I:$I,$K27)="","",INDEX(Checklists!$I:$I,$K27))) | G27: =IF($K27="","",IF(INDEX(Checklists!$J:$J,$K27)="","",INDEX(Checklists!$J:$J,$K27))) | H27: =IF($K27="","",IF(INDEX(Checklists!$K:$K,$K27)="","",INDEX(Checklists!$K:$K,$K27))) | I27: =IF($K27="","",IF(INDEX(Checklists!$L:$L,$K27)="","",INDEX(Checklists!$L:$L,$K27))) | K27: =IFERROR(MATCH(ROWS($K$4:$K27),Checklists!$N$2:$N$291,0)+1,"") | M27: Contratadas | N27: =COUNTIFS(Checklists!$B:$B,$M27,Checklists!$G:$G,"Conforme") -> 0 | O27: =COUNTIFS(Checklists!$B:$B,$M27,Checklists!$G:$G,"Não Conforme") -> 0 | P27: =IF($N27+$O27=0,"",$N27/($N27+$O27))
A28: =IF($K28="","",ROWS($K$4:$K28)) | B28: =IF($K28="","",IF(INDEX(Checklists!$A:$A,$K28)="","",INDEX(Checklists!$A:$A,$K28))) | C28: =IF($K28="","",IF(INDEX(Checklists!$B:$B,$K28)="","",INDEX(Checklists!$B:$B,$K28))) | D28: =IF($K28="","",IF(INDEX(Checklists!$E:$E,$K28)="","",INDEX(Checklists!$E:$E,$K28))) | E28: =IF($K28="","",IF(INDEX(Checklists!$H:$H,$K28)="","",INDEX(Checklists!$H:$H,$K28))) | F28: =IF($K28="","",IF(INDEX(Checklists!$I:$I,$K28)="","",INDEX(Checklists!$I:$I,$K28))) | G28: =IF($K28="","",IF(INDEX(Checklists!$J:$J,$K28)="","",INDEX(Checklists!$J:$J,$K28))) | H28: =IF($K28="","",IF(INDEX(Checklists!$K:$K,$K28)="","",INDEX(Checklists!$K:$K,$K28))) | I28: =IF($K28="","",IF(INDEX(Checklists!$L:$L,$K28)="","",INDEX(Checklists!$L:$L,$K28))) | K28: =IFERROR(MATCH(ROWS($K$4:$K28),Checklists!$N$2:$N$291,0)+1,"") | M28: Produção | N28: =COUNTIFS(Checklists!$B:$B,$M28,Checklists!$G:$G,"Conforme") -> 0 | O28: =COUNTIFS(Checklists!$B:$B,$M28,Checklists!$G:$G,"Não Conforme") -> 0 | P28: =IF($N28+$O28=0,"",$N28/($N28+$O28))
A29: =IF($K29="","",ROWS($K$4:$K29)) | B29: =IF($K29="","",IF(INDEX(Checklists!$A:$A,$K29)="","",INDEX(Checklists!$A:$A,$K29))) | C29: =IF($K29="","",IF(INDEX(Checklists!$B:$B,$K29)="","",INDEX(Checklists!$B:$B,$K29))) | D29: =IF($K29="","",IF(INDEX(Checklists!$E:$E,$K29)="","",INDEX(Checklists!$E:$E,$K29))) | E29: =IF($K29="","",IF(INDEX(Checklists!$H:$H,$K29)="","",INDEX(Checklists!$H:$H,$K29))) | F29: =IF($K29="","",IF(INDEX(Checklists!$I:$I,$K29)="","",INDEX(Checklists!$I:$I,$K29))) | G29: =IF($K29="","",IF(INDEX(Checklists!$J:$J,$K29)="","",INDEX(Checklists!$J:$J,$K29))) | H29: =IF($K29="","",IF(INDEX(Checklists!$K:$K,$K29)="","",INDEX(Checklists!$K:$K,$K29))) | I29: =IF($K29="","",IF(INDEX(Checklists!$L:$L,$K29)="","",INDEX(Checklists!$L:$L,$K29))) | K29: =IFERROR(MATCH(ROWS($K$4:$K29),Checklists!$N$2:$N$291,0)+1,"")
A30: =IF($K30="","",ROWS($K$4:$K30)) | B30: =IF($K30="","",IF(INDEX(Checklists!$A:$A,$K30)="","",INDEX(Checklists!$A:$A,$K30))) | C30: =IF($K30="","",IF(INDEX(Checklists!$B:$B,$K30)="","",INDEX(Checklists!$B:$B,$K30))) | D30: =IF($K30="","",IF(INDEX(Checklists!$E:$E,$K30)="","",INDEX(Checklists!$E:$E,$K30))) | E30: =IF($K30="","",IF(INDEX(Checklists!$H:$H,$K30)="","",INDEX(Checklists!$H:$H,$K30))) | F30: =IF($K30="","",IF(INDEX(Checklists!$I:$I,$K30)="","",INDEX(Checklists!$I:$I,$K30))) | G30: =IF($K30="","",IF(INDEX(Checklists!$J:$J,$K30)="","",INDEX(Checklists!$J:$J,$K30))) | H30: =IF($K30="","",IF(INDEX(Checklists!$K:$K,$K30)="","",INDEX(Checklists!$K:$K,$K30))) | I30: =IF($K30="","",IF(INDEX(Checklists!$L:$L,$K30)="","",INDEX(Checklists!$L:$L,$K30))) | K30: =IFERROR(MATCH(ROWS($K$4:$K30),Checklists!$N$2:$N$291,0)+1,"")
A31: =IF($K31="","",ROWS($K$4:$K31)) | B31: =IF($K31="","",IF(INDEX(Checklists!$A:$A,$K31)="","",INDEX(Checklists!$A:$A,$K31))) | C31: =IF($K31="","",IF(INDEX(Checklists!$B:$B,$K31)="","",INDEX(Checklists!$B:$B,$K31))) | D31: =IF($K31="","",IF(INDEX(Checklists!$E:$E,$K31)="","",INDEX(Checklists!$E:$E,$K31))) | E31: =IF($K31="","",IF(INDEX(Checklists!$H:$H,$K31)="","",INDEX(Checklists!$H:$H,$K31))) | F31: =IF($K31="","",IF(INDEX(Checklists!$I:$I,$K31)="","",INDEX(Checklists!$I:$I,$K31))) | G31: =IF($K31="","",IF(INDEX(Checklists!$J:$J,$K31)="","",INDEX(Checklists!$J:$J,$K31))) | H31: =IF($K31="","",IF(INDEX(Checklists!$K:$K,$K31)="","",INDEX(Checklists!$K:$K,$K31))) | I31: =IF($K31="","",IF(INDEX(Checklists!$L:$L,$K31)="","",INDEX(Checklists!$L:$L,$K31))) | K31: =IFERROR(MATCH(ROWS($K$4:$K31),Checklists!$N$2:$N$291,0)+1,"") | M31: Obs.: as tabelas e os gráficos se atualizam automaticamente conforme as respostas 'Não Conforme' e as evidências forem registradas na aba Checklists.
A32: =IF($K32="","",ROWS($K$4:$K32)) | B32: =IF($K32="","",IF(INDEX(Checklists!$A:$A,$K32)="","",INDEX(Checklists!$A:$A,$K32))) | C32: =IF($K32="","",IF(INDEX(Checklists!$B:$B,$K32)="","",INDEX(Checklists!$B:$B,$K32))) | D32: =IF($K32="","",IF(INDEX(Checklists!$E:$E,$K32)="","",INDEX(Checklists!$E:$E,$K32))) | E32: =IF($K32="","",IF(INDEX(Checklists!$H:$H,$K32)="","",INDEX(Checklists!$H:$H,$K32))) | F32: =IF($K32="","",IF(INDEX(Checklists!$I:$I,$K32)="","",INDEX(Checklists!$I:$I,$K32))) | G32: =IF($K32="","",IF(INDEX(Checklists!$J:$J,$K32)="","",INDEX(Checklists!$J:$J,$K32))) | H32: =IF($K32="","",IF(INDEX(Checklists!$K:$K,$K32)="","",INDEX(Checklists!$K:$K,$K32))) | I32: =IF($K32="","",IF(INDEX(Checklists!$L:$L,$K32)="","",INDEX(Checklists!$L:$L,$K32))) | K32: =IFERROR(MATCH(ROWS($K$4:$K32),Checklists!$N$2:$N$291,0)+1,"")
A33: =IF($K33="","",ROWS($K$4:$K33)) | B33: =IF($K33="","",IF(INDEX(Checklists!$A:$A,$K33)="","",INDEX(Checklists!$A:$A,$K33))) | C33: =IF($K33="","",IF(INDEX(Checklists!$B:$B,$K33)="","",INDEX(Checklists!$B:$B,$K33))) | D33: =IF($K33="","",IF(INDEX(Checklists!$E:$E,$K33)="","",INDEX(Checklists!$E:$E,$K33))) | E33: =IF($K33="","",IF(INDEX(Checklists!$H:$H,$K33)="","",INDEX(Checklists!$H:$H,$K33))) | F33: =IF($K33="","",IF(INDEX(Checklists!$I:$I,$K33)="","",INDEX(Checklists!$I:$I,$K33))) | G33: =IF($K33="","",IF(INDEX(Checklists!$J:$J,$K33)="","",INDEX(Checklists!$J:$J,$K33))) | H33: =IF($K33="","",IF(INDEX(Checklists!$K:$K,$K33)="","",INDEX(Checklists!$K:$K,$K33))) | I33: =IF($K33="","",IF(INDEX(Checklists!$L:$L,$K33)="","",INDEX(Checklists!$L:$L,$K33))) | K33: =IFERROR(MATCH(ROWS($K$4:$K33),Checklists!$N$2:$N$291,0)+1,"")
A34: =IF($K34="","",ROWS($K$4:$K34)) | B34: =IF($K34="","",IF(INDEX(Checklists!$A:$A,$K34)="","",INDEX(Checklists!$A:$A,$K34))) | C34: =IF($K34="","",IF(INDEX(Checklists!$B:$B,$K34)="","",INDEX(Checklists!$B:$B,$K34))) | D34: =IF($K34="","",IF(INDEX(Checklists!$E:$E,$K34)="","",INDEX(Checklists!$E:$E,$K34))) | E34: =IF($K34="","",IF(INDEX(Checklists!$H:$H,$K34)="","",INDEX(Checklists!$H:$H,$K34))) | F34: =IF($K34="","",IF(INDEX(Checklists!$I:$I,$K34)="","",INDEX(Checklists!$I:$I,$K34))) | G34: =IF($K34="","",IF(INDEX(Checklists!$J:$J,$K34)="","",INDEX(Checklists!$J:$J,$K34))) | H34: =IF($K34="","",IF(INDEX(Checklists!$K:$K,$K34)="","",INDEX(Checklists!$K:$K,$K34))) | I34: =IF($K34="","",IF(INDEX(Checklists!$L:$L,$K34)="","",INDEX(Checklists!$L:$L,$K34))) | K34: =IFERROR(MATCH(ROWS($K$4:$K34),Checklists!$N$2:$N$291,0)+1,"")
A35: =IF($K35="","",ROWS($K$4:$K35)) | B35: =IF($K35="","",IF(INDEX(Checklists!$A:$A,$K35)="","",INDEX(Checklists!$A:$A,$K35))) | C35: =IF($K35="","",IF(INDEX(Checklists!$B:$B,$K35)="","",INDEX(Checklists!$B:$B,$K35))) | D35: =IF($K35="","",IF(INDEX(Checklists!$E:$E,$K35)="","",INDEX(Checklists!$E:$E,$K35))) | E35: =IF($K35="","",IF(INDEX(Checklists!$H:$H,$K35)="","",INDEX(Checklists!$H:$H,$K35))) | F35: =IF($K35="","",IF(INDEX(Checklists!$I:$I,$K35)="","",INDEX(Checklists!$I:$I,$K35))) | G35: =IF($K35="","",IF(INDEX(Checklists!$J:$J,$K35)="","",INDEX(Checklists!$J:$J,$K35))) | H35: =IF($K35="","",IF(INDEX(Checklists!$K:$K,$K35)="","",INDEX(Checklists!$K:$K,$K35))) | I35: =IF($K35="","",IF(INDEX(Checklists!$L:$L,$K35)="","",INDEX(Checklists!$L:$L,$K35))) | K35: =IFERROR(MATCH(ROWS($K$4:$K35),Checklists!$N$2:$N$291,0)+1,"")
A36: =IF($K36="","",ROWS($K$4:$K36)) | B36: =IF($K36="","",IF(INDEX(Checklists!$A:$A,$K36)="","",INDEX(Checklists!$A:$A,$K36))) | C36: =IF($K36="","",IF(INDEX(Checklists!$B:$B,$K36)="","",INDEX(Checklists!$B:$B,$K36))) | D36: =IF($K36="","",IF(INDEX(Checklists!$E:$E,$K36)="","",INDEX(Checklists!$E:$E,$K36))) | E36: =IF($K36="","",IF(INDEX(Checklists!$H:$H,$K36)="","",INDEX(Checklists!$H:$H,$K36))) | F36: =IF($K36="","",IF(INDEX(Checklists!$I:$I,$K36)="","",INDEX(Checklists!$I:$I,$K36))) | G36: =IF($K36="","",IF(INDEX(Checklists!$J:$J,$K36)="","",INDEX(Checklists!$J:$J,$K36))) | H36: =IF($K36="","",IF(INDEX(Checklists!$K:$K,$K36)="","",INDEX(Checklists!$K:$K,$K36))) | I36: =IF($K36="","",IF(INDEX(Checklists!$L:$L,$K36)="","",INDEX(Checklists!$L:$L,$K36))) | K36: =IFERROR(MATCH(ROWS($K$4:$K36),Checklists!$N$2:$N$291,0)+1,"")
A37: =IF($K37="","",ROWS($K$4:$K37)) | B37: =IF($K37="","",IF(INDEX(Checklists!$A:$A,$K37)="","",INDEX(Checklists!$A:$A,$K37))) | C37: =IF($K37="","",IF(INDEX(Checklists!$B:$B,$K37)="","",INDEX(Checklists!$B:$B,$K37))) | D37: =IF($K37="","",IF(INDEX(Checklists!$E:$E,$K37)="","",INDEX(Checklists!$E:$E,$K37))) | E37: =IF($K37="","",IF(INDEX(Checklists!$H:$H,$K37)="","",INDEX(Checklists!$H:$H,$K37))) | F37: =IF($K37="","",IF(INDEX(Checklists!$I:$I,$K37)="","",INDEX(Checklists!$I:$I,$K37))) | G37: =IF($K37="","",IF(INDEX(Checklists!$J:$J,$K37)="","",INDEX(Checklists!$J:$J,$K37))) | H37: =IF($K37="","",IF(INDEX(Checklists!$K:$K,$K37)="","",INDEX(Checklists!$K:$K,$K37))) | I37: =IF($K37="","",IF(INDEX(Checklists!$L:$L,$K37)="","",INDEX(Checklists!$L:$L,$K37))) | K37: =IFERROR(MATCH(ROWS($K$4:$K37),Checklists!$N$2:$N$291,0)+1,"")
A38: =IF($K38="","",ROWS($K$4:$K38)) | B38: =IF($K38="","",IF(INDEX(Checklists!$A:$A,$K38)="","",INDEX(Checklists!$A:$A,$K38))) | C38: =IF($K38="","",IF(INDEX(Checklists!$B:$B,$K38)="","",INDEX(Checklists!$B:$B,$K38))) | D38: =IF($K38="","",IF(INDEX(Checklists!$E:$E,$K38)="","",INDEX(Checklists!$E:$E,$K38))) | E38: =IF($K38="","",IF(INDEX(Checklists!$H:$H,$K38)="","",INDEX(Checklists!$H:$H,$K38))) | F38: =IF($K38="","",IF(INDEX(Checklists!$I:$I,$K38)="","",INDEX(Checklists!$I:$I,$K38))) | G38: =IF($K38="","",IF(INDEX(Checklists!$J:$J,$K38)="","",INDEX(Checklists!$J:$J,$K38))) | H38: =IF($K38="","",IF(INDEX(Checklists!$K:$K,$K38)="","",INDEX(Checklists!$K:$K,$K38))) | I38: =IF($K38="","",IF(INDEX(Checklists!$L:$L,$K38)="","",INDEX(Checklists!$L:$L,$K38))) | K38: =IFERROR(MATCH(ROWS($K$4:$K38),Checklists!$N$2:$N$291,0)+1,"")
A39: =IF($K39="","",ROWS($K$4:$K39)) | B39: =IF($K39="","",IF(INDEX(Checklists!$A:$A,$K39)="","",INDEX(Checklists!$A:$A,$K39))) | C39: =IF($K39="","",IF(INDEX(Checklists!$B:$B,$K39)="","",INDEX(Checklists!$B:$B,$K39))) | D39: =IF($K39="","",IF(INDEX(Checklists!$E:$E,$K39)="","",INDEX(Checklists!$E:$E,$K39))) | E39: =IF($K39="","",IF(INDEX(Checklists!$H:$H,$K39)="","",INDEX(Checklists!$H:$H,$K39))) | F39: =IF($K39="","",IF(INDEX(Checklists!$I:$I,$K39)="","",INDEX(Checklists!$I:$I,$K39))) | G39: =IF($K39="","",IF(INDEX(Checklists!$J:$J,$K39)="","",INDEX(Checklists!$J:$J,$K39))) | H39: =IF($K39="","",IF(INDEX(Checklists!$K:$K,$K39)="","",INDEX(Checklists!$K:$K,$K39))) | I39: =IF($K39="","",IF(INDEX(Checklists!$L:$L,$K39)="","",INDEX(Checklists!$L:$L,$K39))) | K39: =IFERROR(MATCH(ROWS($K$4:$K39),Checklists!$N$2:$N$291,0)+1,"")
A40: =IF($K40="","",ROWS($K$4:$K40)) | B40: =IF($K40="","",IF(INDEX(Checklists!$A:$A,$K40)="","",INDEX(Checklists!$A:$A,$K40))) | C40: =IF($K40="","",IF(INDEX(Checklists!$B:$B,$K40)="","",INDEX(Checklists!$B:$B,$K40))) | D40: =IF($K40="","",IF(INDEX(Checklists!$E:$E,$K40)="","",INDEX(Checklists!$E:$E,$K40))) | E40: =IF($K40="","",IF(INDEX(Checklists!$H:$H,$K40)="","",INDEX(Checklists!$H:$H,$K40))) | F40: =IF($K40="","",IF(INDEX(Checklists!$I:$I,$K40)="","",INDEX(Checklists!$I:$I,$K40))) | G40: =IF($K40="","",IF(INDEX(Checklists!$J:$J,$K40)="","",INDEX(Checklists!$J:$J,$K40))) | H40: =IF($K40="","",IF(INDEX(Checklists!$K:$K,$K40)="","",INDEX(Checklists!$K:$K,$K40))) | I40: =IF($K40="","",IF(INDEX(Checklists!$L:$L,$K40)="","",INDEX(Checklists!$L:$L,$K40))) | K40: =IFERROR(MATCH(ROWS($K$4:$K40),Checklists!$N$2:$N$291,0)+1,"")
A41: =IF($K41="","",ROWS($K$4:$K41)) | B41: =IF($K41="","",IF(INDEX(Checklists!$A:$A,$K41)="","",INDEX(Checklists!$A:$A,$K41))) | C41: =IF($K41="","",IF(INDEX(Checklists!$B:$B,$K41)="","",INDEX(Checklists!$B:$B,$K41))) | D41: =IF($K41="","",IF(INDEX(Checklists!$E:$E,$K41)="","",INDEX(Checklists!$E:$E,$K41))) | E41: =IF($K41="","",IF(INDEX(Checklists!$H:$H,$K41)="","",INDEX(Checklists!$H:$H,$K41))) | F41: =IF($K41="","",IF(INDEX(Checklists!$I:$I,$K41)="","",INDEX(Checklists!$I:$I,$K41))) | G41: =IF($K41="","",IF(INDEX(Checklists!$J:$J,$K41)="","",INDEX(Checklists!$J:$J,$K41))) | H41: =IF($K41="","",IF(INDEX(Checklists!$K:$K,$K41)="","",INDEX(Checklists!$K:$K,$K41))) | I41: =IF($K41="","",IF(INDEX(Checklists!$L:$L,$K41)="","",INDEX(Checklists!$L:$L,$K41))) | K41: =IFERROR(MATCH(ROWS($K$4:$K41),Checklists!$N$2:$N$291,0)+1,"")
...
